Workbook

Sheet Сотрудники КЭР
A1: Таб.ном. | B1: ФИО | C1: Подразделение | D1: Руководитель службы/Доступ к расчету КТУ | E1: А-Я | F1: Сокр ФИО | G1: Руководитель в офисе | H1: Осн. Почта для доступа | I1: Осн. тлф | J1: Фирма | K1: Город | L1: Должность | M1: Статус | N1: Доп. Почта | O1: Доп. тлф | P1: Доп. тлф. домашний
A2: 315 | B2: Акмаев Дмитрий Дамирович | C2: Служба ПО | D2: нет | E2: 1 | F2: =LEFT(B2,FIND(" ",B2,1)+1)&"."&MID(B2,FIND(" ",B2,FIND(" ",B2,1)+1)+1,1)&"." -> Акмаев Д.Д. | H2: add.keravt@gmail.com | I2: +7(905)373-30-56 | J2: ООО "КЭР-Автоматика" | K2: г. Набережные Челны | L2: Инженер-программист второй категории | M2: Работает | N2: goreuu@gmail.com
A3: 300 | B3: Антипова Любовь Николаевна | C3: Бухгалтерия | D3: нет | E3: 2 | F3: =LEFT(B3,FIND(" ",B3,1)+1)&"."&MID(B3,FIND(" ",B3,FIND(" ",B3,1)+1)+1,1)&"." -> Антипова Л.Н. | G3: Прасолова Виктория Анатольевна | H3: Aln.keravt@gmail.com | I3: +7 (927) 048-07-60 | J3: ООО "КЭР-Автоматика" | K3: г. Набережные Челны | L3: Заместитель главного бухгалтера | M3: Работает | N3: Aln.keravt@gmail.com
A4: 48 | B4: Ануфриев Сергей Эдуардович | C4: Служба диагностики и ТК | D4: да | E4: 3 | F4: =LEFT(B4,FIND(" ",B4,1)+1)&"."&MID(B4,FIND(" ",B4,FIND(" ",B4,1)+1)+1,1)&"." -> Ануфриев С.Э. | G4: Ануфриев Сергей Эдуардович | H4: ase.keravt@gmail.com | I4: +7 (967) 460-21-77 | J4: ООО "КЭР-Автоматика" | K4: г. Нижнекамск | L4: Начальник службы диагностики и технического контроля | M4: Работает | N4: ase.keravt@gmail.com
A5: 298 | B5: Бабошкина Татьяна Михайловна | C5: Бухгалтерия | D5: нет | E5: 4 | F5: =LEFT(B5,FIND(" ",B5,1)+1)&"."&MID(B5,FIND(" ",B5,FIND(" ",B5,1)+1)+1,1)&"." -> Бабошкина Т.М. | G5: Прасолова Виктория Анатольевна | H5: btm.keravt@gmail.com | I5: +7(917) 861-53-60 | J5: ООО "КЭР-Автоматика" | K5: г. Набережные Челны | L5: Бухгалтер | M5: Работает | N5: btm.keravt@gmail.com
A6: 188 | B6: Белоногов Андрей Николаевич | C6: Уч. ремонта и ТО КИПиА и АСУТП (НК) | D6: нет | E6: 5 | F6: =LEFT(B6,FIND(" ",B6,1)+1)&"."&MID(B6,FIND(" ",B6,FIND(" ",B6,1)+1)+1,1)&"." -> Белоногов А.Н. | I6: +7 (917) 852-29-16 | J6: ООО "КЭР-Автоматика" | K6: г. Нижнекамск | L6: Ведущий инженер по наладке и испытаниям | M6: Болеет | N6: a13andy-fish@mail.ru
A7: 97 | B7: Бирюков Антон Юрьевич | C7: Служба РП | D7: да | E7: 6 | F7: =LEFT(B7,FIND(" ",B7,1)+1)&"."&MID(B7,FIND(" ",B7,FIND(" ",B7,1)+1)+1,1)&"." -> Бирюков А.Ю. | G7: Бирюков Антон Юрьевич | H7: BAY.keravt@gmail.com | I7: +7 (967) 460-18-53 | J7: ООО "КЭР-Автоматика" | K7: г. Казань | L7: Начальник службы проектирования и инженерных изысканий | M7: Работает | N7: BAY.keravt@gmail.com
A8: 104 | B8: Бойцов Дмитрий Николаевич | C8: ОЗиМТО | D8: нет | E8: 7 | F8: =LEFT(B8,FIND(" ",B8,1)+1)&"."&MID(B8,FIND(" ",B8,FIND(" ",B8,1)+1)+1,1)&"." -> Бойцов Д.Н. | G8: Галкин Владимир Александрович | H8: BDN.keravt@gmail.com | I8: +7 (960) 062-11-21 | J8: ООО "КЭР-Автоматика" | K8: г. Набережные Челны | L8: Ведущий инженер по снабжению | M8: Работает | N8: bdn.keravt@gmail.com
A9: 102 | B9: Бойцова Гюзель Рамильевна | C9: ОЗиМТО | D9: нет | E9: 8 | F9: =LEFT(B9,FIND(" ",B9,1)+1)&"."&MID(B9,FIND(" ",B9,FIND(" ",B9,1)+1)+1,1)&"." -> Бойцова Г.Р. | G9: Галкин Владимир Александрович | H9: bgr.keravt@gmail.com | I9: +7 (960) 062-05-40 | J9: ООО "КЭР-Автоматика" | K9: г. Набережные Челны | L9: Экономист по снабжению | M9: Работает | N9: bgr.keravt@gmail.com | P9: +7 (8552) 91-66-11
A10: 135 | B10: Бурдин Александр Сергеевич | C10: Служба наладки | D10: нет | E10: 9 | F10: =LEFT(B10,FIND(" ",B10,1)+1)&"."&MID(B10,FIND(" ",B10,FIND(" ",B10,1)+1)+1,1)&"." -> Бурдин А.С. | H10: BAS.keravt@gmail.com | I10: +7 (967) 460-18-54 | J10: ООО "КЭР-Автоматика" | K10: г. Елабуга | L10: Ведущий инженер по наладке и испытаниям | M10: Работает | N10: BAS.keravt@gmail.com
A11: 158 | B11: Бурунин Владимир Игоревич | C11: Служба ПО | D11: нет | E11: 10 | F11: =LEFT(B11,FIND(" ",B11,1)+1)&"."&MID(B11,FIND(" ",B11,FIND(" ",B11,1)+1)+1,1)&"." -> Бурунин В.И. | H11: BVI.keravt@gmail.com | I11: +7 (960) 062-14-27 | J11: ООО "КЭР-Автоматика" | K11: г. Казань | L11: Начальник службы программного обеспечения | M11: Работает | N11: BVI.keravt@gmail.com
A12: 280 | B12: Васильев Эдуард Андреевич | C12: Служба ПО | D12: нет | E12: 11 | F12: =LEFT(B12,FIND(" ",B12,1)+1)&"."&MID(B12,FIND(" ",B12,FIND(" ",B12,1)+1)+1,1)&"." -> Васильев Э.А. | H12: vea.keravt@gmail.com | I12: +7 (987) 287-67-34 | J12: ООО "КЭР-Автоматика" | K12: г. Казань | L12: Инженер-программист третьей категории | M12: Работает | N12: vea.keravt@gmail.com
A13: 126 | B13: Волков Денис Николаевич | C13: Служба ГС | D13: нет | E13: 12 | F13: =LEFT(B13,FIND(" ",B13,1)+1)&"."&MID(B13,FIND(" ",B13,FIND(" ",B13,1)+1)+1,1)&"." -> Волков Д.Н. | H13: VDN.keravt@gmail.com | I13: +7 (960) 062-13-35 | J13: ООО "КЭР-Автоматика" | K13: г. Казань | L13: Руководитель проектов | M13: Работает | N13: VDN.keravt@gmail.com
A14: 122 | B14: Волкова Лиана Илдаровна | C14: Тендерный отдел | D14: нет | E14: 13 | F14: =LEFT(B14,FIND(" ",B14,1)+1)&"."&MID(B14,FIND(" ",B14,FIND(" ",B14,1)+1)+1,1)&"." -> Волкова Л.И. | H14: VLI.keravt@gmail.com | I14: +7 (966) 240-01-68 | J14: ООО "КЭР-Автоматика" | K14: г. Казань | L14: Инженер по тендерной работе первой категории | M14: Работает | N14: VLI.keravt@gmail.com
A15: 233 | B15: Воронов Артемий Анатольевич | C15: Уч. сборки | D15: нет | E15: 14 | F15: =LEFT(B15,FIND(" ",B15,1)+1)&"."&MID(B15,FIND(" ",B15,FIND(" ",B15,1)+1)+1,1)&"." -> Воронов А.А. | H15: voronovaa.keravt@gmail.com | I15: +7 927 469-23-25 | J15: ООО "КЭР-Автоматика" | K15: г. Набережные Челны | L15: Электрослесарь по обслуживанию и ремонту оборудования третьего разряда | M15: Работает | N15: voronovaa1998@gmail.com
A16: 179 | B16: Ворсина Ирина Александровна | C16: Бухгалтерия | D16: нет | E16: 15 | F16: =LEFT(B16,FIND(" ",B16,1)+1)&"."&MID(B16,FIND(" ",B16,FIND(" ",B16,1)+1)+1,1)&"." -> Ворсина И.А. | G16: Прасолова Виктория Анатольевна | H16: via@keravt.net | I16: +7 (965) 600-04-07 | J16: ООО "КЭР-Автоматика" | K16: г. Набережные Челны | L16: Бухгалтер | M16: Работает | N16: via@keravt.net | O16: +7 (906) 116-72-06 | P16: +7 (8552) 91-55-22
A17: 100 | B17: Гайнутдинов Дамир Фирдинатович | C17: Служба ПО | D17: нет | E17: 16 | F17: =LEFT(B17,FIND(" ",B17,1)+1)&"."&MID(B17,FIND(" ",B17,FIND(" ",B17,1)+1)+1,1)&"." -> Гайнутдинов Д.Ф. | H17: GDF.keravt@gmail.com | I17: +7 (967) 460-18-56 | J17: ООО "КЭР-Автоматика" | K17: г. Казань | L17: Ведущий инженер-программист | M17: Работает | N17: GDF.keravt@gmail.com
A18: 258 | B18: Галиева Ксения Валерьевна | C18: Управление | D18: нет | E18: 17 | F18: =LEFT(B18,FIND(" ",B18,1)+1)&"."&MID(B18,FIND(" ",B18,FIND(" ",B18,1)+1)+1,1)&"." -> Галиева К.В. | G18: Серебрякова Ирина Николаевна | H18: gkv@keravt.net | I18: +7(919)691-71-69 | J18: ООО "КЭР-Автоматика" | K18: г. Набережные Челны | L18: Экономист по финансовой работе | M18: Работает | N18: gkv@keravt.net | O18: +7(919)691-71-69
A19: 74 | B19: Галимуллин Ришат Шамилович | C19: Служба наладки | D19: нет | E19: 18 | F19: =LEFT(B19,FIND(" ",B19,1)+1)&"."&MID(B19,FIND(" ",B19,FIND(" ",B19,1)+1)+1,1)&"." -> Галимуллин Р.Ш. | H19: GRSH.keravt@gmail.com | I19: +7 967 460 1455 | J19: ООО "КЭР-Автоматика" | K19: г. Набережные Челны | L19: Ведущий инженер по наладке и испытаниям | M19: Работает | N19: GRSH.keravt@gmail.com
A20: 195 | B20: Галиуллин Халил Хафизович | C20: Уч. ремонта и ТО КИПиА и АСУТП (НК) | D20: нет | E20: 19 | F20: =LEFT(B20,FIND(" ",B20,1)+1)&"."&MID(B20,FIND(" ",B20,FIND(" ",B20,1)+1)+1,1)&"." -> Галиуллин Х.Х. | J20: ООО "КЭР-Автоматика" | K20: г. Нижнекамск | L20: Электрослесарь по ремонту и обслуживанию автоматики и средств измерений электростанций седьмого разряда | M20: Работает | N20: galiullinhh8@gmail.com | O20: +7 (917) 860-49-62
A21: 218 | B21: Гарифуллин Рим Ризаевич | C21: Служба РП | D21: нет | E21: 20 | F21: =LEFT(B21,FIND(" ",B21,1)+1)&"."&MID(B21,FIND(" ",B21,FIND(" ",B21,1)+1)+1,1)&"." -> Гарифуллин Р.Р. | G21: Бирюков Антон Юрьевич | H21: GRR.keravt@gmail.com | I21: +7 (937)276-90-44 | J21: ООО "КЭР-Автоматика" | K21: г. Казань | L21: Инженер-проектировщик первой категории | M21: Работает | N21: rizaevich@rambler.ru
A22: 133 | B22: Гафурова Оксана Владимировна | C22: Бухгалтерия | D22: нет | E22: 21 | F22: =LEFT(B22,FIND(" ",B22,1)+1)&"."&MID(B22,FIND(" ",B22,FIND(" ",B22,1)+1)+1,1)&"." -> Гафурова О.В. | G22: Прасолова Виктория Анатольевна | H22: gov@keravt.net | I22: +7 (987) 189-92-79 | J22: ООО "КЭР-Автоматика" | K22: г. Набережные Челны | L22: Бухгалтер | M22: Работает | N22: gov@keravt.net | P22: +7 (8552) 91-55-22
A23: 147 | B23: Гильфанов Радик Хуснимухаметович | C23: ОЗиМТО | D23: нет | E23: 22 | F23: =LEFT(B23,FIND(" ",B23,1)+1)&"."&MID(B23,FIND(" ",B23,FIND(" ",B23,1)+1)+1,1)&"." -> Гильфанов Р.Х. | G23: Галкин Владимир Александрович | I23: +7 (960) 062-14-59 | J23: ООО "КЭР-Автоматика" | K23: г. Набережные Челны | L23: Агент по снабжению | M23: Работает | N23: radja_xxx@mail.ru | O23: +7 (917) 278-62-64
A24: 189 | B24: Гоголева Ирина Ханифовна | C24: Уч. ремонта и ТО КИПиА и АСУТП (НК) | D24: нет | E24: 23 | F24: =LEFT(B24,FIND(" ",B24,1)+1)&"."&MID(B24,FIND(" ",B24,FIND(" ",B24,1)+1)+1,1)&"." -> Гоголева И.Х. | I24: +7 (987) 294-72-52 | J24: ООО "КЭР-Автоматика" | K24: г. Нижнекамск | L24: Инженер по проектно-сметной работе | M24: Работает | N24: irgogoleva@bk.ru
A25: 252 | B25: Григорьева Елена Станиславна | C25: Служба РП | D25: нет | E25: 24 | F25: =LEFT(B25,FIND(" ",B25,1)+1)&"."&MID(B25,FIND(" ",B25,FIND(" ",B25,1)+1)+1,1)&"." -> Григорьева Е.С. | G25: Бирюков Антон Юрьевич | H25: GES.keravt@gmail.com | I25: +7 (937) 526-53-96 | J25: ООО "КЭР-Автоматика" | K25: г. Казань | L25: Ведущий инженер-проектировщик | M25: Работает | N25: GES.keravt@gmail.com
A26: 332 | B26: Губаев Ильдар Найлевич | C26: Служба ПО | D26: нет | E26: 25 | F26: =LEFT(B26,FIND(" ",B26,1)+1)&"."&MID(B26,FIND(" ",B26,FIND(" ",B26,1)+1)+1,1)&"." -> Губаев И.Н. | H26: gin.keravt@gmail.com | I26: +7 (939) 381-15-35 | J26: ООО "КЭР-Автоматика" | K26: г. Казань | L26: Инженер-программист второй категории | M26: Работает
A27: 241 | B27: Гурьянов Андрей Николаевич | C27: Уч. ремонта и ТО КИПиА и АСУТП (НК) | D27: нет | E27: 26 | F27: =LEFT(B27,FIND(" ",B27,1)+1)&"."&MID(B27,FIND(" ",B27,FIND(" ",B27,1)+1)+1,1)&"." -> Гурьянов А.Н. | J27: ООО "КЭР-Автоматика" | K27: г. Нижнекамск | L27: Инженер по обслуживанию охранно-пожарной сигнализации | M27: Работает | N27: gur-andrei2010@mail.ru | O27: 8(917)282-85-68
A28: 325 | B28: Дарвиш Самер Юсеф Мустафа | C28: Уч. сборки | D28: нет | E28: 27 | F28: =LEFT(B28,FIND(" ",B28,1)+1)&"."&MID(B28,FIND(" ",B28,FIND(" ",B28,1)+1)+1,1)&"." -> Дарвиш С.Ю. | I28: +7(965) 588-59-82 | J28: ООО "КЭР-Автоматика" | K28: г. Набережные Челны | L28: Начальник участка | M28: Работает | N28: dsy.keravt@gmail.com | O28: +7(965) 588-59-82
A29: 176 | B29: Дмитриченко Дмитрий Федорович | C29: Уч. ремонта и ТО КИПиА и АСУТП (НК) | D29: нет | E29: 28 | F29: =LEFT(B29,FIND(" ",B29,1)+1)&"."&MID(B29,FIND(" ",B29,FIND(" ",B29,1)+1)+1,1)&"." -> Дмитриченко Д.Ф. | I29: +7 (917) 294-56-54 | J29: ООО "КЭР-Автоматика" | K29: г. Нижнекамск | L29: Инженер по наладке и испытаниям первой категории | M29: Работает | N29: dmitrichenko.dimitri@yandex.ru
A30: 180 | B30: Дорогов Иван Владимирович | C30: Служба наладки | D30: нет | E30: 29 | F30: =LEFT(B30,FIND(" ",B30,1)+1)&"."&MID(B30,FIND(" ",B30,FIND(" ",B30,1)+1)+1,1)&"." -> Дорогов И.В. | H30: DIV.keravt@gmail.com | I30: +7 (996) 558-32-79 | J30: ООО "КЭР-Автоматика" | K30: г. Томск | L30: Инженер по наладке и испытаниям первой категории | M30: Работает | N30: dorogov-i@yandex.ru | O30: +7 (771) 120-35-97
A31: 160 | B31: Дьякова Ольга Валерьевна | C31: Отдел поддержки ПО | D31: да | E31: 30 | F31: =LEFT(B31,FIND(" ",B31,1)+1)&"."&MID(B31,FIND(" ",B31,FIND(" ",B31,1)+1)+1,1)&"." -> Дьякова О.В. | G31: Дьякова Ольга Валерьевна | H31: dov.keravt@gmail.com | I31: +7 (960) 069-01-46 | J31: ООО "КЭР-Автоматика" | K31: г. Набережные Челны | L31: Начальник отдела поддержки программного обеспечения | M31: Работает | N31: dov@keravt.net
A32: 167 | B32: Егоров Степан Владимирович | C32: Уч. ремонта и ТО КИПиА и АСУТП (НК) | D32: нет | E32: 31 | F32: =LEFT(B32,FIND(" ",B32,1)+1)&"."&MID(B32,FIND(" ",B32,FIND(" ",B32,1)+1)+1,1)&"." -> Егоров С.В. | H32: esv.keravt@gmail.com | I32: +7 (965) 588-45-57 | J32: ООО "КЭР-Автоматика" | K32: г. Нижнекамск | L32: Начальник участка | M32: Работает | N32: egorovstepan@mail.ru | O32: +7 (965) 588-57-04
A33: 108 | B33: Ермолаева Роза Ринатовна | C33: Отдел подготовки ТД | D33: нет | E33: 32 | F33: =LEFT(B33,FIND(" ",B33,1)+1)&"."&MID(B33,FIND(" ",B33,FIND(" ",B33,1)+1)+1,1)&"." -> Ермолаева Р.Р. | H33: ERR.keravt@gmail.com | I33: +7 (967) 460-21-59 | J33: ООО "КЭР-Автоматика" | K33: г. Казань | L33: Инженер | M33: Работает | N33: ERR.keravt@gmail.com
A34: 121 | B34: Зарянова Диана Васильевна | C34: Тендерный отдел | D34: нет | E34: 33 | F34: =LEFT(B34,FIND(" ",B34,1)+1)&"."&MID(B34,FIND(" ",B34,FIND(" ",B34,1)+1)+1,1)&"." -> Зарянова Д.В. | H34: zdv.keravt@gmail.com | I34: +7 (960) 062-21-75 | J34: ООО "КЭР-Автоматика" | K34: г. Казань | L34: Начальник тендерного отдела | M34: Работает | N34: zdv.keravt@gmail.com
A35: 196 | B35: Зыков Николай Александрович | C35: Уч. ремонта и ТО КИПиА и АСУТП (НК) | D35: нет | E35: 34 | F35: =LEFT(B35,FIND(" ",B35,1)+1)&"."&MID(B35,FIND(" ",B35,FIND(" ",B35,1)+1)+1,1)&"." -> Зыков Н.А. | J35: ООО "КЭР-Автоматика" | K35: г. Нижнекамск | L35: Электрослесарь по ремонту и обслуживанию автоматики и средств измерений электростанций седьмого разряда | M35: Работает | N35: aloriks25z@yandex.ru | O35: +7 (917) 939-32-66
A36: 303 | B36: Ибрагимов Ирек Азатович | C36: Служба диагностики и ТК | D36: нет | E36: 35 | F36: =LEFT(B36,FIND(" ",B36,1)+1)&"."&MID(B36,FIND(" ",B36,FIND(" ",B36,1)+1)+1,1)&"." -> Ибрагимов И.А. | H36: ibragimovia.keravt@gmail.com | I36: +7(987)413-18-68 | J36: ООО "КЭР-Автоматика" | K36: г. Казань | L36: Инженер по наладке и испытаниям | M36: Работает | N36: irek.ibragimov.1990@mail.ru
A37: 171 | B37: Иванов Юрий Владимирович | C37: Уч. ремонта и ТО КИПиА и АСУТП (НК) | D37: нет | E37: 36 | F37: =LEFT(B37,FIND(" ",B37,1)+1)&"."&MID(B37,FIND(" ",B37,FIND(" ",B37,1)+1)+1,1)&"." -> Иванов Ю.В. | I37: +7 (962) 571-98-35 | J37: ООО "КЭР-Автоматика" | K37: г. Нижнекамск | L37: Электрослесарь по ремонту и обслуживанию автоматики и средств измерений электростанций четвертого разряда | M37: Работает | N37: urij0035@gmail.com
A38: 131 | B38: Илалова Мария Николаевна | C38: ОЗиМТО | D38: нет | E38: 37 | F38: =LEFT(B38,FIND(" ",B38,1)+1)&"."&MID(B38,FIND(" ",B38,FIND(" ",B38,1)+1)+1,1)&"." -> Илалова М.Н. | G38: Галкин Владимир Александрович | H38: IMN.keravt@gmail.com | I38: +7 (967) 460-18-55 | J38: ООО "КЭР-Автоматика" | K38: г. Набережные Челны | L38: Экономист по снабжению | M38: Работает | N38: IMN.keravt@gmail.com | O38: +7 (906) 120-00-22
A39: 80 | B39: Исаева Ольга Александровна | C39: Отдел кадров | D39: да | E39: 38 | F39: =LEFT(B39,FIND(" ",B39,1)+1)&"."&MID(B39,FIND(" ",B39,FIND(" ",B39,1)+1)+1,1)&"." -> Исаева О.А. | G39: Исаева Ольга Александровна | H39: IOA.keravt@gmail.com | I39: +7 (960) 062-07-19 | J39: ООО "КЭР-Автоматика" | K39: г. Набережные Челны | L39: Начальник отдела кадров | M39: Работает | N39: ioa@keravt.net | P39: +7 (8552) 91-44-22
A40: 222 | B40: Исламов Фарит Рашитович | C40: Уч. ремонта и ТО КИПиА и АСУТП (НК) | D40: нет | E40: 39 | F40: =LEFT(B40,FIND(" ",B40,1)+1)&"."&MID(B40,FIND(" ",B40,FIND(" ",B40,1)+1)+1,1)&"." -> Исламов Ф.Р. | J40: ООО "КЭР-Автоматика" | K40: г. Нижнекамск | L40: Электрогазосварщик шестого разряда | M40: Работает | N40: islamov.farrid@yandex.ru | O40: +7 (917) 912-61-86
...

Sheet Сотрудники УЭС
A1: Штатное расписание | F1: последний элемент списка | G1: =COUNTIF(E3:E43,"<>" & "") -> 41
A2: Таб.ном. | B2: ФИО | C2: Подразделение | D2: Руководитель службы/Доступ к расчету КТУ | E2: А-Я | F2: Сокр ФИО | G2: Руководитель в офисе | H2: Осн. Почта для доступа | I2: Осн. тлф | J2: Фирма | K2: Город | L2: Должность | M2: Статус | N2: Доп. Почта | O2: Доп. тлф | P2: Доп. тлф. домашний
A3: 86 | B3: Абдуллин Рафаэль Равилевич | C3: Служба ГС | D3: нет | E3: 1 | F3: =LEFT(B3,FIND(" ",B3,1)+1)&"."&MID(B3,FIND(" ",B3,FIND(" ",B3,1)+1)+1,1)&"." -> Абдуллин Р.Р. | H3: arr.keravt@gmail.com | I3: +7(906) 328-76-12 | J3: ООО "УЭС-Автоматика" | K3: г. Набережные Челны | L3: Руководитель проектов | M3: Работает | N3: arr.keravt@gmail.com
A4: 119 | B4: Андреев Владимир Николаевич | C4: Уч. монтажа КИПиА и АСУТП (Ел) | D4: нет | E4: 2 | F4: =LEFT(B4,FIND(" ",B4,1)+1)&"."&MID(B4,FIND(" ",B4,FIND(" ",B4,1)+1)+1,1)&"." -> Андреев В.Н. | I4: +7(960) 612-88-35 | J4: ООО "УЭС-Автоматика" | K4: г. Новомосковск | L4: Электромонтер по ремонту и обслуживанию электрооборудования пятого разряда | M4: В отпуске без сохранения зарплаты | N4: AndreevVN1970@yandex.ru
A5: 62 | B5: Андреев Юрий Анатольевич | C5: Служба ГС | D5: нет | E5: 3 | F5: =LEFT(B5,FIND(" ",B5,1)+1)&"."&MID(B5,FIND(" ",B5,FIND(" ",B5,1)+1)+1,1)&"." -> Андреев Ю.А. | H5: aya.keravt@gmail.com | J5: ООО "УЭС-Автоматика" | K5: г. Казань | L5: Руководитель проектов | M5: Работает | N5: sm200562@mail.ru | O5: +7 (917) 399-66-42
A6: 91 | B6: Аухадиев Рустам Борисович | C6: Тендерный отдел | D6: нет | E6: 4 | F6: =LEFT(B6,FIND(" ",B6,1)+1)&"."&MID(B6,FIND(" ",B6,FIND(" ",B6,1)+1)+1,1)&"." -> Аухадиев Р.Б. | H6: arb.keravt@gmail.com | I6: +7(953) 498-33-07 | J6: ООО "УЭС-Автоматика" | K6: г. Казань | L6: Инженер по технико-коммерческой работе второй категории | M6: Работает | N6: arb.keravt@gmail.com
A7: 59 | B7: Безрукавый Антон Олегович (осн.) | C7: Служба наладки | D7: нет | E7: 5 | F7: =LEFT(B7,FIND(" ",B7,1)+1)&"."&MID(B7,FIND(" ",B7,FIND(" ",B7,1)+1)+1,1)&"." -> Безрукавый А.О. | H7: bao.keravt@gmail.com | I7: +7( 953) 806-70-36 | J7: ООО "УЭС-Автоматика" | K7: г. Казань | L7: Инженер по наладке и испытаниям первой категории | M7: Работает | N7: axtox111@yandex.ru
A8: 77 | B8: Богачев Юрий Васильевич | C8: Уч. монтажа КИПиА и АСУТП (Ел) | D8: нет | E8: 6 | F8: =LEFT(B8,FIND(" ",B8,1)+1)&"."&MID(B8,FIND(" ",B8,FIND(" ",B8,1)+1)+1,1)&"." -> Богачев Ю.В. | I8: +7(964) 117-89-39 | J8: ООО "УЭС-Автоматика" | K8: г. Новомосковск | L8: Электромонтажник | M8: Работает | N8: boghachiov1986@mail.ru
A9: 61 | B9: Власов Василий Александрович | C9: Уч. монтажа КИПиА и АСУТП (Ел) | D9: нет | E9: 7 | F9: =LEFT(B9,FIND(" ",B9,1)+1)&"."&MID(B9,FIND(" ",B9,FIND(" ",B9,1)+1)+1,1)&"." -> Власов В.А. | I9: +7(914) 898-65-65 | J9: ООО "УЭС-Автоматика" | K9: г. Новомосковск | L9: Начальник участка | M9: Работает | N9: 27121974vlasov@mail.ru
A10: 115 | B10: Воробьев Владимир Сергеевич | C10: Уч. монтажа КИПиА и АСУТП (Ел) | D10: нет | E10: 8 | F10: =LEFT(B10,FIND(" ",B10,1)+1)&"."&MID(B10,FIND(" ",B10,FIND(" ",B10,1)+1)+1,1)&"." -> Воробьев В.С. | I10: +7 (950) 111-31-81 | J10: ООО "УЭС-Автоматика" | K10: г. Новомосковск | L10: Электросварщик ручной сварки четвертого разряда | M10: Работает | N10: vorobei-vova89@mail.ru
A11: 8 | B11: Габдрахманов Рустам Мисбахович | C11: Служба РП | D11: нет | E11: 9 | F11: =LEFT(B11,FIND(" ",B11,1)+1)&"."&MID(B11,FIND(" ",B11,FIND(" ",B11,1)+1)+1,1)&"." -> Габдрахманов Р.М. | H11: GRM.keravt@gmail.com | I11: +7(950)327-50-73 | J11: ООО "УЭС-Автоматика" | K11: г. Набережные Челны | L11: Ведущий инженер-проектировщик | M11: Работает | N11: GRM.keravt@gmail.com
A12: 7 | B12: Габдрахманова Ания Разиновна | C12: Служба РП | D12: нет | E12: 10 | F12: =LEFT(B12,FIND(" ",B12,1)+1)&"."&MID(B12,FIND(" ",B12,FIND(" ",B12,1)+1)+1,1)&"." -> Габдрахманова А.Р. | H12: GAR.keravt@gmail.com | I12: +7 (950) 327-95-83 | J12: ООО "УЭС-Автоматика" | K12: г. Набережные Челны | L12: Главный инженер проекта | M12: Работает | N12: GAR.keravt@gmail.com
A13: 108 | B13: Говорухин Александр Сергеевич | C13: Уч. монтажа КИПиА и АСУТП (Ел) | D13: нет | E13: 11 | F13: =LEFT(B13,FIND(" ",B13,1)+1)&"."&MID(B13,FIND(" ",B13,FIND(" ",B13,1)+1)+1,1)&"." -> Говорухин А.С. | I13: +7(905)186-58-21 | J13: ООО "УЭС-Автоматика" | K13: г. Новомосковск | L13: Электромонтажник третьего разряда | M13: Работает | N13: sagasany@yandex.ru
A14: 122 | B14: Григорьев Евгений Александрович | C14: Уч. монтажа КИПиА и АСУТП (Ел) | D14: нет | E14: 12 | F14: =LEFT(B14,FIND(" ",B14,1)+1)&"."&MID(B14,FIND(" ",B14,FIND(" ",B14,1)+1)+1,1)&"." -> Григорьев Е.А. | I14: +7 (920) 748-63-59 | J14: ООО "УЭС-Автоматика" | K14: г. Новомосковск | L14: Электромонтер по ремонту и обслуживанию электрооборудования пятого разряда | M14: Работает | N14: EVGGrigoreb@gmail.com
A15: 37 | B15: Гуляев Сергей Алексеевич | C15: Служба ГС | D15: нет | E15: 13 | F15: =LEFT(B15,FIND(" ",B15,1)+1)&"."&MID(B15,FIND(" ",B15,FIND(" ",B15,1)+1)+1,1)&"." -> Гуляев С.А. | H15: gsa.keravt@gmail.com | I15: +7 (960) 062-15-79 | J15: ООО "УЭС-Автоматика" | K15: г. Казань | L15: Руководитель проектов | M15: Работает | N15: gsa.keravt@gmail.com
A16: 73 | B16: Епишин Алексей Александрович | C16: Уч. монтажа КИПиА и АСУТП (Ел) | D16: нет | E16: 14 | F16: =LEFT(B16,FIND(" ",B16,1)+1)&"."&MID(B16,FIND(" ",B16,FIND(" ",B16,1)+1)+1,1)&"." -> Епишин А.А. | I16: +7 (950) 909-51-11 | J16: ООО "УЭС-Автоматика" | K16: г. Новомосковск | L16: Мастер | M16: Работает | N16: aleksei.seeqerd@yandex.ru
A17: 66 | B17: Зарипов Рушан Расулевич (осн.) | C17: Служба наладки | D17: нет | E17: 15 | F17: =LEFT(B17,FIND(" ",B17,1)+1)&"."&MID(B17,FIND(" ",B17,FIND(" ",B17,1)+1)+1,1)&"." -> Зарипов Р.Р. | H17: Yurneroru@gmail.com | I17: +7 (987)221-11-87 | J17: ООО "УЭС-Автоматика" | K17: г. Казань | L17: Инженер по наладке и испытаниям второй категории | M17: Работает | N17: Yurneroru@gmail.com
A18: 113 | B18: Ключников Станислав Владимирович | C18: Уч. монтажа КИПиА и АСУТП (Ел) | D18: нет | E18: 16 | F18: =LEFT(B18,FIND(" ",B18,1)+1)&"."&MID(B18,FIND(" ",B18,FIND(" ",B18,1)+1)+1,1)&"." -> Ключников С.В. | I18: +7(980) 014-94-78 | J18: ООО "УЭС-Автоматика" | K18: г. Новомосковск | L18: Электромонтажник - наладчик пятого разряда | M18: Работает | N18: klucnikovstanislav87@gmail.com
A19: 74 | B19: Копылов Иван Анатольевич | C19: Уч. монтажа КИПиА и АСУТП (Ел) | D19: нет | E19: 17 | F19: =LEFT(B19,FIND(" ",B19,1)+1)&"."&MID(B19,FIND(" ",B19,FIND(" ",B19,1)+1)+1,1)&"." -> Копылов И.А. | I19: +7(983) 448-02-21 | J19: ООО "УЭС-Автоматика" | K19: г. Новомосковск | L19: Электромонтажник | M19: Работает | N19: vanechka.kopylov.94@bk.ru
A20: 79 | B20: Корнеев Сергей Аркадьевич | C20: Уч. монтажа КИПиА и АСУТП (Ел) | D20: нет | E20: 18 | F20: =LEFT(B20,FIND(" ",B20,1)+1)&"."&MID(B20,FIND(" ",B20,FIND(" ",B20,1)+1)+1,1)&"." -> Корнеев С.А. | J20: ООО "УЭС-Автоматика" | K20: г. Новомосковск | L20: Электромонтажник - наладчик четвертого разряда | M20: Работает | N20: cerega.korneev@yandex.ru
A21: 28 | B21: Кулаков Денис Анатольевич | C21: Служба РП | D21: нет | E21: 19 | F21: =LEFT(B21,FIND(" ",B21,1)+1)&"."&MID(B21,FIND(" ",B21,FIND(" ",B21,1)+1)+1,1)&"." -> Кулаков Д.А. | H21: kda.keravt@gmail.com | I21: +7 (960) 061-98-73 | J21: ООО "УЭС-Автоматика" | K21: г. Казань | L21: Заместитель генерального директора по проектированию | M21: Работает | N21: kda.keravt@gmail.com
A22: 80 | B22: Литвинов Александр Юрьевич | C22: Уч. монтажа КИПиА и АСУТП (Ел) | D22: нет | E22: 20 | F22: =LEFT(B22,FIND(" ",B22,1)+1)&"."&MID(B22,FIND(" ",B22,FIND(" ",B22,1)+1)+1,1)&"." -> Литвинов А.Ю. | J22: ООО "УЭС-Автоматика" | K22: г. Новомосковск | L22: Мастер | M22: Работает | N22: lit.71jolt@gmail.com
A23: 64 | B23: Макаров Алексей Васильевич | C23: Служба наладки | D23: нет | E23: 21 | F23: =LEFT(B23,FIND(" ",B23,1)+1)&"."&MID(B23,FIND(" ",B23,FIND(" ",B23,1)+1)+1,1)&"." -> Макаров А.В. | H23: makarovav.keravt@gmail.com | J23: ООО "УЭС-Автоматика" | K23: г. Набережные Челны | L23: Инженер по наладке и испытаниям первой категории | M23: Работает | N23: makarov.proma@yandex.ru | O23: +7 (937) 619-67-50
A24: 101 | B24: Мужеков Ирек Рассихович | C24: Служба ПО | D24: нет | E24: 22 | F24: =LEFT(B24,FIND(" ",B24,1)+1)&"."&MID(B24,FIND(" ",B24,FIND(" ",B24,1)+1)+1,1)&"." -> Мужеков И.Р. | H24: mir.keravt@gmail.com | I24: +7(963)120-54-37 | J24: ООО "УЭС-Автоматика" | K24: г. Казань | L24: Техник-программист второй категории | M24: Болеет | N24: mir.keravt@gmail.com | O24: +7(963)120-54-37
A25: 120 | B25: Пахомов Роман Владиславович | C25: Уч. монтажа КИПиА и АСУТП (Ел) | D25: нет | E25: 23 | F25: =LEFT(B25,FIND(" ",B25,1)+1)&"."&MID(B25,FIND(" ",B25,FIND(" ",B25,1)+1)+1,1)&"." -> Пахомов Р.В. | I25: +7(960) 608-40-42 | J25: ООО "УЭС-Автоматика" | K25: г. Новомосковск | L25: Электромонтер по ремонту и обслуживанию электрооборудования пятого разряда | M25: В отпуске без сохранения зарплаты | N25: pakhomov.romka@yandex.ru
A26: 53 | B26: Платонов Денис Андреевич | C26: Служба РП | D26: нет | E26: 24 | F26: =LEFT(B26,FIND(" ",B26,1)+1)&"."&MID(B26,FIND(" ",B26,FIND(" ",B26,1)+1)+1,1)&"." -> Платонов Д.А. | H26: pda.keravt@gmail.com | J26: ООО "УЭС-Автоматика" | K26: г. Казань | L26: Ученик инженера-проектировщика | M26: Работает | N26: pda.keravt@gmail.com | O26: +7(919)622-54-60
A27: 121 | B27: Пронин Сергей Николаевич | C27: Уч. монтажа КИПиА и АСУТП (Ел) | D27: нет | E27: 25 | F27: =LEFT(B27,FIND(" ",B27,1)+1)&"."&MID(B27,FIND(" ",B27,FIND(" ",B27,1)+1)+1,1)&"." -> Пронин С.Н. | I27: +7(903) 421-82-74 | J27: ООО "УЭС-Автоматика" | K27: г. Новомосковск | L27: Электромонтер по ремонту и обслуживанию электрооборудования четвертого разряда | M27: В отпуске без сохранения зарплаты | N27: Serezha.PN2011@yandex.ru
A28: 112 | B28: Раянова Лилиана Рафисовна | C28: Тендерный отдел | D28: нет | E28: 26 | F28: =LEFT(B28,FIND(" ",B28,1)+1)&"."&MID(B28,FIND(" ",B28,FIND(" ",B28,1)+1)+1,1)&"." -> Раянова Л.Р. | H28: rlr.keravt@gmail.com | I28: +7 (986) 704-31-32 | J28: ООО "УЭС-Автоматика" | K28: г. Казань | L28: Инженер по технико-коммерческой работе второй категории | M28: Работает | N28: rlr.keravt@gmail.com
A29: 125 | B29: Рыскаль Владимир Андреевич | C29: ЭТД | D29: нет | E29: 27 | F29: =LEFT(B29,FIND(" ",B29,1)+1)&"."&MID(B29,FIND(" ",B29,FIND(" ",B29,1)+1)+1,1)&"." -> Рыскаль В.А. | I29: +7 (960) 061-98-57 | J29: ООО "УЭС-Автоматика" | K29: г. Казань | L29: Заместитель технического директора | M29: Работает | N29: rva.keravt@gmail.com
A30: 123 | B30: Садыков Ильшат Рушанович | C30: Служба ГС | D30: нет | E30: 28 | F30: =LEFT(B30,FIND(" ",B30,1)+1)&"."&MID(B30,FIND(" ",B30,FIND(" ",B30,1)+1)+1,1)&"." -> Садыков И.Р. | H30: sir.keravt@gmail.com | I30: +7 (960) 062-19-80 | J30: ООО "УЭС-Автоматика" | K30: г. Казань | L30: Руководитель проектов | M30: Работает | N30: sir.keravt@gmail.com
A31: 6 | B31: Самохвалов Андрей Викторович | C31: Служба РП | D31: нет | E31: 29 | F31: =LEFT(B31,FIND(" ",B31,1)+1)&"."&MID(B31,FIND(" ",B31,FIND(" ",B31,1)+1)+1,1)&"." -> Самохвалов А.В. | H31: samav.keravt@gmail.com | I31: +7 (927) 244-99-94 | J31: ООО "УЭС-Автоматика" | K31: г. Набережные Челны | L31: Главный инженер проекта | M31: В ежегодном отпуске | N31: samav.keravt@gmail.com
A32: 34 | B32: Семенов Денис Александрович | C32: Служба ГС | D32: нет | E32: 30 | F32: =LEFT(B32,FIND(" ",B32,1)+1)&"."&MID(B32,FIND(" ",B32,FIND(" ",B32,1)+1)+1,1)&"." -> Семенов Д.А. | H32: SDA.keravt@gmail.com | I32: +7 (960) 062-16-84 | J32: ООО "УЭС-Автоматика" | K32: г. Казань | L32: Руководитель проектов | M32: Работает | N32: SDA.keravt@gmail.com
A33: 81 | B33: Семиженко Александр Васильевич | C33: ОЗиМТО | D33: нет | E33: 31 | F33: =LEFT(B33,FIND(" ",B33,1)+1)&"."&MID(B33,FIND(" ",B33,FIND(" ",B33,1)+1)+1,1)&"." -> Семиженко А.В. | H33: SAV.keravt@gmail.com | I33: +7 (960) 061-95-16 | J33: ООО "УЭС-Автоматика" | K33: г. Набережные Челны | L33: Ведущий инженер по снабжению | M33: Работает | N33: SAV.keravt@gmail.com
A34: 94 | B34: Стихарев Виктор Викторович | C34: Уч. монтажа КИПиА и АСУТП (Ел) | D34: нет | E34: 32 | F34: =LEFT(B34,FIND(" ",B34,1)+1)&"."&MID(B34,FIND(" ",B34,FIND(" ",B34,1)+1)+1,1)&"." -> Стихарев В.В. | J34: ООО "УЭС-Автоматика" | K34: г. Новомосковск | L34: Электромонтажник - наладчик пятого разряда | M34: Работает | N34: barin787@rambler.ru
A35: 52 | B35: Турпак Александр Михайлович | C35: Служба РП | D35: нет | E35: 33 | F35: =LEFT(B35,FIND(" ",B35,1)+1)&"."&MID(B35,FIND(" ",B35,FIND(" ",B35,1)+1)+1,1)&"." -> Турпак А.М. | H35: turpak.keravt@gmail.com | I35: +7(922)330-26-23 | J35: ООО "УЭС-Автоматика" | K35: г. Набережные Челны | L35: Инженер-проектировщик второй категории | M35: Работает | N35: turpakam@yandex.ru | O35: +7(922)330-26-23
A36: 54 | B36: Унгурян Руслан Викторович | C36: ЭТД | D36: нет | E36: 34 | F36: =LEFT(B36,FIND(" ",B36,1)+1)&"."&MID(B36,FIND(" ",B36,FIND(" ",B36,1)+1)+1,1)&"." -> Унгурян Р.В. | H36: urv.keravt@gmail.com | I36: +7 (967) 460-14-32 | J36: ООО "УЭС-Автоматика" | K36: г. Казань | L36: Заместитель главного инженера | M36: Работает | N36: rusangelvsr@gmail.com
A37: 60 | B37: Флегонтов Дмитрий Олегович | C37: Служба ПО | D37: нет | E37: 35 | F37: =LEFT(B37,FIND(" ",B37,1)+1)&"."&MID(B37,FIND(" ",B37,FIND(" ",B37,1)+1)+1,1)&"." -> Флегонтов Д.О. | H37: fdo.keravt@gmail.com | I37: +7(987)267-44-17 | J37: ООО "УЭС-Автоматика" | K37: г. Казань | L37: Инженер-программист первой категории | M37: Работает | N37: fdo.keravt@gmail.com
A38: 114 | B38: Фомин Евгений Дмитриевич | C38: Уч. монтажа КИПиА и АСУТП (Ел) | D38: нет | E38: 36 | F38: =LEFT(B38,FIND(" ",B38,1)+1)&"."&MID(B38,FIND(" ",B38,FIND(" ",B38,1)+1)+1,1)&"." -> Фомин Е.Д. | I38: +7 (980) 562-13-93 | J38: ООО "УЭС-Автоматика" | K38: г. Новомосковск | L38: Электромонтажник | M38: Работает | N38: evgen1980proton@gmail.com
A39: 12 | B39: Фролов Сергей Александрович | C39: ЭТД | D39: нет | E39: 37 | F39: =LEFT(B39,FIND(" ",B39,1)+1)&"."&MID(B39,FIND(" ",B39,FIND(" ",B39,1)+1)+1,1)&"." -> Фролов С.А. | H39: FSA.keravt@gmail.com | I39: +7 (960) 061-99-86 | J39: ООО "УЭС-Автоматика" | K39: г. Набережные Челны | L39: Главный инженер | M39: Работает | N39: FSA.keravt@gmail.com | P39: +7 (8552) 91-44-11
A40: 69 | B40: Хабибуллин Булат Ринатович | C40: Служба ПО | D40: нет | E40: 38 | F40: =LEFT(B40,FIND(" ",B40,1)+1)&"."&MID(B40,FIND(" ",B40,FIND(" ",B40,1)+1)+1,1)&"." -> Хабибуллин Б.Р. | H40: kbr.keravt@gmail.com | I40: +7 (987) 423-47-35 | J40: ООО "УЭС-Автоматика" | K40: г. Казань | L40: Ведущий инженер-программист | M40: Работает | N40: kbr.keravt@gmail.com
...

Sheet Сотрудники КАРНО
A1: Штатное расписание | F1: последний элемент списка | G1: =COUNTIF(E3:E6,"<>" & "") -> 4
A2: Таб.ном. | B2: ФИО | C2: Подразделение | D2: Руководитель службы/Доступ к расчету КТУ | E2: А-Я | F2: Сокр ФИО | G2: Руководитель в офисе | H2: Осн. Почта для доступа | I2: Осн. тлф | J2: Фирма | K2: Город | L2: Должность | M2: Статус | N2: Доп. Почта | O2: Доп. тлф | P2: Доп. тлф. домашний
A3: 3 | B3: Воронов Анатолий Николаевич (осн.) | C3: Управление | D3: нет | E3: 1 | F3: =LEFT(B3,FIND(" ",B3,1)+1)&"."&MID(B3,FIND(" ",B3,FIND(" ",B3,1)+1)+1,1)&"." -> Воронов А.Н. | H3: van.keravt@gmail.com | I3: +7 (960) 062-14-04 | J3: ООО "Карно-Энерго" | K3: г. Набережные Челны | L3: Генеральный директор | M3: Работает | N3: van.keravt@gmail.com
A4: 12 | B4: Миронов Александр Александрович | D4: нет | E4: 2 | F4: =LEFT(B4,FIND(" ",B4,1)+1)&"."&MID(B4,FIND(" ",B4,FIND(" ",B4,1)+1)+1,1)&"." -> Миронов А.А. | H4: maa.keravt@gmail.com | I4: +7 (960) 062-32-14 | J4: ООО "Карно-Энерго" | K4: г. Набережные Челны | L4: Ведущий инженер по наладке и испытаниям | M4: Работает
A5: 10 | B5: Пилецкий Дмитрий Евгеньевич | C5: Управление | D5: нет | E5: 3 | F5: =LEFT(B5,FIND(" ",B5,1)+1)&"."&MID(B5,FIND(" ",B5,FIND(" ",B5,1)+1)+1,1)&"." -> Пилецкий Д.Е. | H5: pde.keravt@gmail.com | I5: +7 (965) 619-22-22 | J5: ООО "Карно-Энерго" | K5: г. Набережные Челны | L5: Заместитель технического директора | M5: Работает | N5: piletskyde@gmail.com | P5: +7 (8552) 91-44-11
A6: 8 | B6: Шугаева Марина Евгеньевна | C6: Управление | D6: нет | E6: 4 | F6: =LEFT(B6,FIND(" ",B6,1)+1)&"."&MID(B6,FIND(" ",B6,FIND(" ",B6,1)+1)+1,1)&"." -> Шугаева М.Е. | H6: SME.keravt@gmail.com | I6: +7 (906) 333-21-11 | J6: ООО "Карно-Энерго" | K6: г. Набережные Челны | L6: Главный бухгалтер | M6: Работает | N6: sme@keravt.net | P6: +7 (8552) 91-33-11

Sheet Сотрудники АЙВИС
A1: Штатное расписание | F1: последний элемент списка | G1: =COUNTIF(E3:E8,"<>" & "") -> 6
A2: Таб.ном. | B2: ФИО | C2: Подразделение | D2: Руководитель службы/Доступ к расчету КТУ | E2: А-Я | F2: Сокр ФИО | G2: Руководитель в офисе | H2: Осн. Почта для доступа | I2: Осн. тлф | J2: Фирма | K2: Город | L2: Должность | M2: Статус | N2: Доп. Почта | O2: Доп. тлф | P2: Доп. тлф. домашний
A3: 1 | B3: Хибатуллин Алмаз Нурмухаметович | C3: Управление | D3: нет | E3: 1 | F3: =LEFT(B3,FIND(" ",B3,1)+1)&"."&MID(B3,FIND(" ",B3,FIND(" ",B3,1)+1)+1,1)&"." -> Хибатуллин А.Н. | G3: Исаева О.А. | H3: almazkhibatullin@gmail.com | I3: +7 965 622-99-10 | J3: ООО "Айвис" | K3: г. Казань | L3: Главный специалист по защите информации | M3: Работает | N3: dyx.90@mail.ru
A4: 2 | B4: Корсаков Сергей Евгеньевич | C4: Управление | D4: нет | E4: 2 | F4: =LEFT(B4,FIND(" ",B4,1)+1)&"."&MID(B4,FIND(" ",B4,FIND(" ",B4,1)+1)+1,1)&"." -> Корсаков С.Е. | G4: Сабиров А.М. | H4: KSE.keravt@gmail.com | I4: +7 967 460-14-33 | J4: ООО "Айвис" | K4: г. Казань | L4: Генеральный директор | M4: Работает
A5: 3 | B5: Мыкало Светлана Алексеевна | C5: Управление | D5: нет | E5: 3 | F5: =LEFT(B5,FIND(" ",B5,1)+1)&"."&MID(B5,FIND(" ",B5,FIND(" ",B5,1)+1)+1,1)&"." -> Мыкало С.А. | G5: Галкин В.А. | H5: MykaloSA.keravt@gmail.com | I5: +7 960 062-11-41 | J5: ООО "Айвис" | K5: г. Казань | L5: Заместитель генерального директора | M5: Работает
A6: 4 | B6: Зарянов Валерий Геннадьевич | C6: Управление | D6: нет | E6: 4 | F6: =LEFT(B6,FIND(" ",B6,1)+1)&"."&MID(B6,FIND(" ",B6,FIND(" ",B6,1)+1)+1,1)&"." -> Зарянов В.Г. | G6: Сабиров А.М. | H6: ZVG.keravt@gmail.com | I6: +7 967 460-14-39 | J6: ООО "Айвис" | K6: г. Казань | L6: Начальник отдела программного обеспечения | M6: Работает
A7: 5 | B7: Филиппов Алексей Владимирович | C7: Управление | D7: нет | E7: 5 | F7: =LEFT(B7,FIND(" ",B7,1)+1)&"."&MID(B7,FIND(" ",B7,FIND(" ",B7,1)+1)+1,1)&"." -> Филиппов А.В. | G7: Пилецкий Д.Е. | H7: fav.keravt@gmail.com | I7: +7 951 894-60-93 | J7: ООО "Айвис" | K7: г. Набережные Челны | L7: Специалист по информационным технологиям | M7: Работает | N7: kalmah11@mail.ru
A8: 6 | B8: Кияметдинов Ильмир Харисович | C8: Программист | D8: нет | E8: 6 | F8: =LEFT(B8,FIND(" ",B8,1)+1)&"."&MID(B8,FIND(" ",B8,FIND(" ",B8,1)+1)+1,1)&"." -> Кияметдинов И.Х. | G8: Унгурян Р.В. | H8: kih.keravt@gmail.com | I8: +7 960 045-96-10 | J8: ООО "Айвис" | K8: г. Казань | L8: Программист | M8: Работает | N8: ilmir2007@inbox.ru

Sheet Внештаные сотрудники
A1: Штатное расписание | F1: последний элемент списка | G1: =COUNTIF(E3:E8,"<>" & "") -> 6
A2: Таб.ном. | B2: ФИО | C2: Подразделение | D2: Руководитель службы/Доступ к расчету КТУ | E2: А-Я | F2: Сокр ФИО | G2: Руководитель в офисе | H2: Осн. Почта для доступа | I2: Осн. тлф | J2: Фирма | K2: Город | L2: Должность | M2: Статус | N2: Доп. Почта | O2: Доп. тлф | P2: Доп. тлф. домашний
A3: -1 | B3: Погодин Дмитрий Дмитриевич | C3: Управление | D3: нет | E3: 1 | F3: =LEFT(B3,FIND(" ",B3,1)+1)&"."&MID(B3,FIND(" ",B3,FIND(" ",B3,1)+1)+1,1)&"." -> Погодин Д.Д. | G3: Сабиров А.М. | H3: pogodindd@gmail.com | I3: +7 960 062-13-90 | J3: ООО "КЭР-Автоматика" | K3: г. Казань | L3: Руководитель службы метрологического обеспечения | M3: Работает
A4: -2 | B4: Саркисян Вадим Сергеевич | C4: Уч. сборки | D4: нет | E4: 2 | F4: Саркисян В.С. | G4: Сабиров А.М. | H4: svs.keravt@gmail.com | I4: +7 960 062-22-04 | J4: ООО "Карно-Энерго" | K4: г. Казань | L4: Руководитель проектов | M4: Работает
A5: -3 | B5: Функ Александр Иванович | C5: Сотрудники РК | D5: нет | E5: 3 | F5: =LEFT(B5,FIND(" ",B5,1)+1)&"."&MID(B5,FIND(" ",B5,FIND(" ",B5,1)+1)+1,1)&"." -> Функ А.И. | H5: fai.keravt@gmail.com | I5: +7 701 213-39-10 | J5: ООО "КЭР-Автоматика" | K5: г. Караганда | L5: Инженер АСУТП | M5: Работает | N5: funk-93@mail.ru
A6: -4 | B6: Сумин Евгений Владимирович | C6: Сотрудники РК | D6: нет | E6: 4 | F6: =LEFT(B6,FIND(" ",B6,1)+1)&"."&MID(B6,FIND(" ",B6,FIND(" ",B6,1)+1)+1,1)&"." -> Сумин Е.В. | H6: SuminEV.keravt@gmail.com | I6: +7 707 607-58-68 | J6: ООО "КЭР-Автоматика" | K6: г. Павлодар | L6: Инженер АСУТП | M6: Работает | N6: Prizrak_angel@mail.ru
A7: -5 | B7: Аркаев Александр Сергеевич | C7: Сотрудники РК | D7: нет | E7: 5 | F7: =LEFT(B7,FIND(" ",B7,1)+1)&"."&MID(B7,FIND(" ",B7,FIND(" ",B7,1)+1)+1,1)&"." -> Аркаев А.С. | H7: aas.keravt@gmail.com | I7: +7 705 670-35-40 | J7: ООО "КЭР-Автоматика" | K7: г. Павлодар | L7: Инженер АСУТП | M7: Работает | N7: arksan.work@ya.ru
A8: -6 | B8: Жеребцов Антон Александрович | C8: Сотрудники РК | D8: нет | E8: 6 | F8: Жеребцов А.А. | H8: ZherebtsovAA.keravt@gmail.com | I8: +7 777 461-19-85 | J8: ООО "КЭР-Автоматика" | K8: г. Павлодар | L8: Инженер АСУТП | M8: Работает | N8: antalger@mail.ru

Sheet Совместительство
A1: Штатное расписание | F1: последний элемент списка | G1: =COUNTIF(E3,"<>" & "") -> 1
A2: Таб.ном. | B2: ФИО | C2: Подразделение | D2: Руководитель службы/Доступ к расчету КТУ | E2: А-Я | F2: Сокр ФИО | G2: Руководитель в офисе | H2: Осн. Почта для доступа | I2: Осн. тлф | J2: Фирма | K2: Город | L2: Должность | M2: Статус | N2: Доп. Почта | O2: Доп. тлф | P2: Доп. тлф. домашний
A3: 66 | B3: Зубрия Владимир Анатольевич | C3: Служба диагностики и ТК | D3: нет | E3: 5 | F3: =LEFT(B3,FIND(" ",B3,1)+1)&"."&MID(B3,FIND(" ",B3,FIND(" ",B3,1)+1)+1,1)&"." -> Зубрия В.А. | G3: Ануфриев Сергей Эдуардович | I3: +7 (919) 634-56-04 | J3: ООО "КЭР-Автоматика" | K3: г. Набережные Челны | L3: Инженер | M3: В отпуске без сохранения зарплаты | N3: zubriava@yandex.ru

Sheet Отделы
A1: Список | B1: Генерация файлов отчетов | C1: Status create | D1: Сокращенное имя | E1: Участие в расчете коэф-та сложности бесполезная штука но нужна | F1: URL папки отдела | G1: URL rкниги отдела | H1: Создавать для этой службы табель? | I1: 23
A2: Служба диагностики и ТК | B2: FALSE | C2: FALSE | D2: Служба диагностики и ТК | H2: FALSE
A3: Служба ПО | B3: TRUE | C3: TRUE | D3: Служба ПО | F3: 1fDwv_PDcKMkkQiu2YSrKu1rhuAmZOREY | G3: 1NPV4vMc3xDjFtXACkapoGWqiBjhDXEct82fG-Dv6I2w | H3: TRUE
A4: Уч. сборки | B4: TRUE | C4: TRUE | D4: Уч. сборки | F4: 19tbOUcAMw5F5A8QS9zOB9dWKXLMysBsp | G4: 16qlpxW9mDsG0YUvMOBNlwHyhMsDRVpgOo1JxYN7DzPA | H4: TRUE
A5: Уч. монтажа КИПиА и АСУТП (Ел) | B5: FALSE | C5: FALSE | D5: Уч. монтажа КИПиА и АСУТП (Ел) | H5: FALSE
A6: Служба наладки | B6: TRUE | C6: TRUE | D6: Служба наладки | F6: 1awxmEfkXK5UrHrIC0wLF4LzAVfPhZy_L | G6: 1zj7IvdFuBzUioCBOqrjplfoUYJvJ3AO4neXte9I1MiI | H6: TRUE
A7: Служба РП | B7: TRUE | C7: TRUE | D7: Служба РП | F7: 1Y7RjlxP8qE74l4mnuO8arN3_0vGXuLcy | G7: 1S66RD_mjFyWUMjwL8G4cjwKQQCJYG8EXheQblGhmL0c | H7: TRUE
A8: Уч. ремонта и ТО КИПиА и АСУТП (НК) | B8: FALSE | C8: FALSE | D8: Уч. ремонта и ТО КИПиА и АСУТП (НК) | H8: FALSE
A9: ОЗиМТО | B9: TRUE | C9: TRUE | D9: ОЗиМТО | F9: 1nSyMuQ_xSRtCwiZ9_o95FCKTB8MeA4WG | G9: 1z9jMqVzajRHj2rVuvOZHd5-9-IYRsNHgESil0kI-oKU | H9: TRUE
A10: Тендерный отдел | B10: TRUE | C10: TRUE | D10: Тендерный отдел | F10: 14BCGkDMMbXGpF28Hg5wtQSge9CFHzskr | G10: 1BA26_oJBh1709PURrvGmugP52Qc_Eo-cizHpNbpTcZw | H10: TRUE
A11: Служба ГС | B11: TRUE | C11: TRUE | D11: Служба ГС | F11: 1VXCAo2hjyftpafQg2vqICQwmfM4LEQnL | G11: 1NC52laa27RT1FV9X85ptvJQXDtpygoFgl_KZXYjXi44 | H11: TRUE
A12: Бухгалтерия | B12: FALSE | C12: FALSE | D12: Бухгалтерия | H12: FALSE
A13: Управление | B13: FALSE | C13: FALSE | D13: Управление | F13: 1LdcVo7at0VQVE40Y7eI54USH0kYKzWVs | G13: 1kdFOZj2_NLske9sPP72olmLx-TxG4_X5NRZRQRWVj04 | H13: FALSE
A14: ЭТД | B14: FALSE | C14: FALSE | D14: ЭТД | H14: FALSE
A15: Отдел поддержки ПО | B15: FALSE | C15: FALSE | D15: Отдел поддержки ПО | H15: FALSE
A16: Отдел подготовки ТД | B16: TRUE | C16: TRUE | D16: Отдел подготовки ТД | F16: 1D0_Vzn1V_pjaTyvRIeC6IRZZD1r-pWJe | G16: 1grjMbJiqfSQbQtFhjQz7810l4e-pD0UaVca0r0AczfE | H16: TRUE
A17: Договорной отдел | B17: FALSE | C17: FALSE | D17: Договорной отдел | H17: FALSE
A18: Отдел кадров | B18: FALSE | C18: FALSE | D18: Отдел кадров | H18: FALSE
A19: Служба СО АСУТП | B19: FALSE | C19: FALSE | D19: Служба СО АСУТП | H19: FALSE
A20: Отдел ОТ и ТБ | B20: FALSE | C20: FALSE | D20: Отдел ОТ и ТБ | H20: FALSE
A21: Отдел ДО | B21: FALSE | C21: FALSE | D21: Отдел ДО | H21: FALSE
A22: Отдел ИТ | B22: FALSE | C22: FALSE | D22: Отдел ИТ | H22: FALSE
A23: Сотрудники РК | B23: TRUE | C23: TRUE | D23: Сотрудники РК | F23: 1XHxhlHUQXfwrhIzxymtW5IjaZazowAJq | G23: 1XNuzT0hAckXmfwVqyl59NXpE3-D9222PY5gYw0k08oE | H23: TRUE
A24: Программист | B24: TRUE | C24: TRUE | D24: Программист | F24: 1_vMhPy-jHqy4QMkFaYziDK9RNdf2zKTx | G24: 1DjNyPjO7qr5CNVXBGXce9p-eBIGDZreLAFKLosdxdK0 | H24: TRUE

Sheet Список книг
A1: Main/NameBooks | B1: Main/BooksID | D1: Main/NameFolder | E1: Main/FolderID | F1: Main/Test
A2: Имя книги | B2: ID | D2: Имя папки | E2: ID
A3: Уч. сборки | B3: =Отделы!G4 -> 16qlpxW9mDsG0YUvMOBNlwHyhMsDRVpgOo1JxYN7DzPA | D3: =Отделы!D4 -> Уч. сборки | E3: =Отделы!F4 -> 19tbOUcAMw5F5A8QS9zOB9dWKXLMysBsp
A4: =Отделы!A5 -> Уч. монтажа КИПиА и АСУТП (Ел) | B4: =Отделы!G5 -> 0 | D4: =Отделы!D5 -> Уч. монтажа КИПиА и АСУТП (Ел) | E4: =Отделы!F5 -> 0
A5: =Отделы!A2 -> Служба диагностики и ТК | B5: =Отделы!G2 -> 0 | D5: =Отделы!D2 -> Служба диагностики и ТК | E5: =Отделы!F2 -> 0
A6: =Отделы!A6 -> Служба наладки | B6: =Отделы!G6 -> 1zj7IvdFuBzUioCBOqrjplfoUYJvJ3AO4neXte9I1MiI | D6: =Отделы!D6 -> Служба наладки | E6: =Отделы!F6 -> 1awxmEfkXK5UrHrIC0wLF4LzAVfPhZy_L
A7: =Отделы!A7 -> Служба РП | B7: =Отделы!G7 -> 1S66RD_mjFyWUMjwL8G4cjwKQQCJYG8EXheQblGhmL0c | D7: =Отделы!D7 -> Служба РП | E7: =Отделы!F7 -> 1Y7RjlxP8qE74l4mnuO8arN3_0vGXuLcy
A8: =Отделы!A8 -> Уч. ремонта и ТО КИПиА и АСУТП (НК) | B8: =Отделы!G8 -> 0 | D8: =Отделы!D8 -> Уч. ремонта и ТО КИПиА и АСУТП (НК) | E8: =Отделы!F8 -> 0
A9: =Отделы!A9 -> ОЗиМТО | B9: =Отделы!G9 -> 1z9jMqVzajRHj2rVuvOZHd5-9-IYRsNHgESil0kI-oKU | D9: =Отделы!D9 -> ОЗиМТО | E9: =Отделы!F9 -> 1nSyMuQ_xSRtCwiZ9_o95FCKTB8MeA4WG
A10: =Отделы!A10 -> Тендерный отдел | B10: =Отделы!G10 -> 1BA26_oJBh1709PURrvGmugP52Qc_Eo-cizHpNbpTcZw | D10: =Отделы!D10 -> Тендерный отдел | E10: =Отделы!F10 -> 14BCGkDMMbXGpF28Hg5wtQSge9CFHzskr
A11: =Отделы!A3 -> Служба ПО | B11: =Отделы!G3 -> 1NPV4vMc3xDjFtXACkapoGWqiBjhDXEct82fG-Dv6I2w | D11: =Отделы!D3 -> Служба ПО | E11: =Отделы!F3 -> 1fDwv_PDcKMkkQiu2YSrKu1rhuAmZOREY
A12: =Отделы!A11 -> Служба ГС | B12: =Отделы!G11 -> 1NC52laa27RT1FV9X85ptvJQXDtpygoFgl_KZXYjXi44 | D12: =Отделы!D11 -> Служба ГС | E12: =Отделы!F11 -> 1VXCAo2hjyftpafQg2vqICQwmfM4LEQnL
A13: =Отделы!A12 -> Бухгалтерия | B13: =Отделы!G12 -> 0 | D13: =Отделы!D12 -> Бухгалтерия | E13: =Отделы!F12 -> 0
A14: =Отделы!A13 -> Управление | B14: =Отделы!G13 -> 1kdFOZj2_NLske9sPP72olmLx-TxG4_X5NRZRQRWVj04 | D14: =Отделы!D13 -> Управление | E14: =Отделы!F13 -> 1LdcVo7at0VQVE40Y7eI54USH0kYKzWVs
A15: =Отделы!A14 -> ЭТД | B15: =Отделы!G14 -> 0 | D15: =Отделы!D14 -> ЭТД | E15: =Отделы!F14 -> 0
A16: =Отделы!A15 -> Отдел поддержки ПО | B16: =Отделы!G15 -> 0 | D16: =Отделы!D15 -> Отдел поддержки ПО | E16: =Отделы!F15 -> 0
A17: =Отделы!A16 -> Отдел подготовки ТД | B17: =Отделы!G16 -> 1grjMbJiqfSQbQtFhjQz7810l4e-pD0UaVca0r0AczfE | D17: =Отделы!D16 -> Отдел подготовки ТД | E17: =Отделы!F16 -> 1D0_Vzn1V_pjaTyvRIeC6IRZZD1r-pWJe
A18: =Отделы!A17 -> Договорной отдел | B18: =Отделы!G17 -> 0 | D18: =Отделы!D17 -> Договорной отдел | E18: =Отделы!F17 -> 0
A19: =Отделы!A18 -> Отдел кадров | B19: =Отделы!G18 -> 0 | D19: =Отделы!D18 -> Отдел кадров | E19: =Отделы!F18 -> 0
A20: =Отделы!A19 -> Служба СО АСУТП | B20: =Отделы!G19 -> 0 | D20: =Отделы!D19 -> Служба СО АСУТП | E20: =Отделы!F19 -> 0
A21: =Отделы!A20 -> Отдел ОТ и ТБ | B21: =Отделы!G20 -> 0 | D21: =Отделы!D20 -> Отдел ОТ и ТБ | E21: =Отделы!F20 -> 0
A22: =Отделы!A21 -> Отдел ДО | B22: =Отделы!G21 -> 0 | D22: =Отделы!D21 -> Отдел ДО | E22: =Отделы!F21 -> 0
A23: =Отделы!A22 -> Отдел ИТ | B23: =Отделы!G22 -> 0 | D23: =Отделы!D22 -> Отдел ИТ | E23: =Отделы!F22 -> 0
A24: Реестр проектов | B24: 1QukVP206RlzrQVRFJjikyza1vxmDdWkzH4NOQmOjneA | D24: Реестр проектов | E24: 1L-M16EAoK1jWQnucnia-SZ8d2QhHdpIH
A25: Штатное расписание | B25: 1p7_jSKEaCgPYZHPTzQIH-ZXY20atv5WLMlUThCM-JqA | D25: КЭР-Автоматика | E25: 1dAdiKlZVNqYWy3FHhzvYP9SH_-hCU0W-
A26: Управление Google User | B26: 1Ts4iNHnLwzgfZeaeMmf9NpNOMqI_Fu6mM3mUcWC1NgI | D26: УЭС-Автоматика | E26: 1d95cTToyL7z6WRaM2kT3rk-5ChSLzEcv
A27: Бойцова Г.Р. КЭР 2020 | B27: 1kZwAYpiEKLC1gE5I55tVH2v3OizmN2jl_SQt65JbnDk | D27: КАРНО-Энерго | E27: 1TyVgaSFOUdfwwTd23roM3_lLBIzBKDuw
A28: Илалова М.Н. КЭР 2020 | B28: 1qr_PTPWUceV7BPTEcmrEA3vZhCrtaHHKuXe1aN9n7_g | D28: АЙВИС | E28: 11Ijwurmc_bz7fIFhC93RkOZod4tssW9a
A29: Куницына Н.Е. КЭР 2020 | B29: 15LkKuIg1fXlljryJ2pxxY56SpjN1gLkc5kbktl3yi38 | D29: Отчеты служб | E29: 1MY4tOkLUM66h_DMzPSwzVtWRw5DJ3Our
A30: Мыкало С.А. КЭР 2020 | B30: 1vVM_MOILD2o_SmvW--BPSroxr18cwg-0VTMqETiYnls | D30: Контрагенты КЭР | E30: 1bJ9OLL1AhnonQgJr6HE1Gum3LcHIb9EY
A31: Файрушина О.А. КЭР 2020 | B31: 1qZok7PmbeVGipO4uK4ImsvhavTf8q_ZMf10AIPgPMFw | D31: Табели | E31: 1OMC8NWdH7oNSA2-JR7VZwPa8zmfgIDwD
A32: Карно-Энерго график отпусков 2020 | B32: 1R6mSCZ2NLawmTHP4EdvygE05kwSmmdSd-zXk9eiS4yY | D32: Контрагенты УЭС | E32: 1ipu-SmzBny1ZjOheFymxcknpacGoVRH0
A33: КЭР-Автоматика график отпусков 2020 | B33: 1aA0P3hia_Pjc8BUSVe0F2nJuVYex80ORxERHB-zjjxg | D33: Контрагенты КАРНО | E33: 1F6WjBejL1KaTl2lO-JtW9jEdDask70kY
A34: УЭС-Автоматика график отпусков 2020 | B34: 1lJOXpqkQGshPzGb5hjnbaOgMDEARNMCB9LNkxvktqE8 | D34: Расчет КТУ | E34: 1lOkVOVos3ObZmJQx8EAG07SJ9ClX0W8r
A35: 2020 Реестр проектов | B35: 19W26m-_YLGcwtbJspW4jp1jNnulW_U716Wl8bojGmI8 | D35: ТКР | E35: 1Hw_N4iWKHeviUFaFZe-_behj9loHCuKQ
... A38: Мыкало С.А. ТОО 2020 | B38: 1lXZ4fFZwtW_J0mL8bKIX1xHE2T3YfBmSwxCaWBCfzPY | D38: Программист | E38: 1_vMhPy-jHqy4QMkFaYziDK9RNdf2zKTx
A39: Карно-Энерго график отпусков 2020 | B39: 1R6mSCZ2NLawmTHP4EdvygE05kwSmmdSd-zXk9eiS4yY
A40: КЭР-Автоматика график отпусков 2020 | B40: 1aA0P3hia_Pjc8BUSVe0F2nJuVYex80ORxERHB-zjjxg
A41: УЭС-Автоматика график отпусков 2020 | B41: 1lJOXpqkQGshPzGb5hjnbaOgMDEARNMCB9LNkxvktqE8
A42: Сборка шкафов | B42: 1aJvM205i5Q1Djp1KxIOttAK78df4Y_VkpEHLfBFIMCg
...

Sheet Список контрагентов
A1: Main/agent | B1: Main/inn | C1: Main/kpp
A2: Контрагент | B2: ИНН | C2: КПП
A3: 12 СТУЛЬЕВ КЗ ООО | B3: ООО "12 СТУЛЬЕВ КЗ" | C3: 1657203880
A4: ComplyWorks Ltd. | B4: ComplyWorks Ltd.
A5: FRIGUIA S.A. | B5: FRIGUIA S.A.
A6: GROUPE INNOVATION TECHNOLOGIQUE | B6: GROUPE INNOVATION TECHNOLOGIQUE
A7: АБН ООО | B7: ООО "АБН" | C7: 7730640648
A8: АБН ТД, ООО | B8: ООО ТД "АБН" | C8: 7731262780
A9: АБС Групп ООО | B9: ООО "АБС Групп" | C9: 1657248190
A10: АБС ЗЭиМ Автоматизация АО | B10: АО "АБС ЗЭиМ Автоматизация" | C10: 2128006240
A11: Абсолют Банк, Акционерный коммерческий банк, ПАО | B11: АКБ "Абсолют Банк" (ПАО) | C11: 7736046991
A12: АБСОЛЮТ СТРАХОВАНИЕ ООО | B12: ООО "АБСОЛЮТ СТРАХОВАНИЕ" | C12: 7728178835
A13: Авеон ООО | B13: ООО "Авеон" | C13: 6658205551
A14: Авеон-трейд ООО | B14: ООО "Авеон-трейд" | C14: 6670350883
A15: Аверс Банк ООО | B15: ООО Банк "Аверс" | C15: 1653003601
A16: Авиакомпания АЗИМУТ АО | B16: АО "АВИАКОМПАНИЯ АЗИМУТ" | C16: 2312218415
A17: Авиакомпания АЗУР ЭЙР ООО | B17: ОБЩЕСТВО С ОГРАНИЧЕННОЙ ОТВЕТСТВЕННОСТЬЮ "АЗУР ЭЙР" | C17: 2459007621
A18: Авиакомпания АЭРОФЛОТ ПАО | B18: ПУБЛИЧНОЕ АКЦИОНЕРНОЕ ОБЩЕСТВО "АЭРОФЛОТ-РОССИЙСКИЕ АВИАЛИНИИ" | C18: 7712040126
... A78: Амосов Василь Владимирович | B78: Амосов Василь Владимирович | C78: 165036266597
A79: АМХ ИНЖИНИРИНГ БЕЛ ООО | B79: ООО "АМХ ИНЖИНИРИНГ БЕЛ"
A80: Аналитех НПЦ, ООО | B80: ООО "НПЦ "Аналитех" | C80: 5262254403
A81: Аналитические приборы ТД, ООО | B81: ООО "ТД "Аналитические приборы" | C81: 6729038941
A82: АНАЛИТИЧЕСКИЙ ЦЕНТР,АО | B82: АО "АНАЛИТИЧЕСКИЙ ЦЕНТР" | C82: 5260270696
A83: АНАЛИТПРИБОР, СПО ФГУП | B83: ФГУП "СПО "АНАЛИТПРИБОР" | C83: 6731002766
A84: АналитТеплоКонтроль, ООО | B84: ООО "АналитТеплоКонтроль" | C84: 6731062123
A85: Андращук Кирилл Сергеевич ИП | B85: Индивидуальный предприниматель Андращук Кирилл Сергеевич | C85: 673008440521
A86: АНКОР ИБ ООО | B86: ООО "Инженерное Бюро "АНКОР" | C86: 1661023369
A87: Антей ООО | B87: ООО "Антей" | C87: 7706786357
A88: Ануфриев Сергей Эдуардович | B88: Ануфриев Сергей Эдуардович | C88: 165106630348
A89: АПАТОР Группа ООО | B89: ООО Группа "АПАТОР" | C89: 7716704314
A90: Апекс-аудит ООО | B90: ООО "Апекс-аудит" | C90: 1831019549
A91: АПРЕЛЬ.РУ ООО | B91: ООО "АПРЕЛЬ.РУ" | C91: 1650285500
... A123: Байкал-Сервис Набережные Челны, ООО | B123: ООО "Байкал-Сервис Набережные Челны" | C123: 1650172070
A124: Байкал-Сервис ООО | B124: ООО "Байкал-Сервис"
A125: Байкал-Сервис ТК, ООО | B125: ООО "Байкал-Сервис ТК" | C125: 5001038736
A126: Балтийский лизинг АО | B126: АО "Балтийский лизинг" | C126: 7812022787
A127: Балтийский лизинг, ООО | B127: ООО "Балтийский лизинг" | C127: 7826705374
A128: Балясникова Анастасия Александровна | B128: Балясникова Анастасия Александровна | C128: 31402088937
A129: Баннова Аграфена Алексеевна | B129: Баннова Аграфена Алексеевна | C129: 31401947600
A130: БАРС-ЭЛЕКТРО ООО | B130: ООО "БАРС-ЭЛЕКТРО" | C130: 1656089928
...

Sheet temp
A1: Фирмы | C1: Имя папки | D1: URL папки | F1: Замена служб сокр. службами | I1: Выпадающий список "Размещение" | J1: Праздники | K1: Офиц. № проекта | L1: Сокр. Имя для списка | M1: Выпадающий список "Работа" | N1: Руководитель проекта | O1: Выпадающий список "Вид работ"
A2: ООО "КЭР-Автоматика" | C2: Отчеты служб | D2: 1MY4tOkLUM66h_DMzPSwzVtWRw5DJ3Our | F2: Участок сборки оборудования | G2: Уч. сборки | I2: Офис | J2: 44564 | L2: Внутренние работы | M2: Внутренние работы | O2: Комплексная работа
A3: ООО "УЭС-Автоматика" | C3: Данные персонала\КЭР-Автоматика | D3: 1l6DAnfN-GwGi3nl50QwkvHZbEO2R8zf4 | F3: Участок по монтажу КИПиА и АСУТП | G3: Уч. монтажа КИПиА и АСУТП (Ел) | I3: Объект | J3: 44565 | L3: Административные вопросы | M3: Административные вопросы | O3: Техническое задание
A4: ООО "Карно-Энерго" | C4: Данные персонала\УЭС-Автоматика | D4: 1Lwh2EPl6GwSZ-emOjNfQv5pamjgIMv3r | F4: Служба диагностики и технического контроля | G4: Служба диагностики и ТК | I4: Дом | J4: 44566 | L4: НИОКР | M4: НИОКР | O4: Техническое предложение
A5: ООО "Айвис" | C5: Данные персонала\КАРНО-Энерго | D5: 1Nz0u5IbfsxIuuxdNjcV1SVlJq_layt3P | F5: Служба наладки и испытаний | G5: Служба наладки | I5: Отгул | J5: 44567 | L5: ТКП | M5: ТКП | O5: Расчет
C6: Департамент\Реестр проектов | D6: 1L-M16EAoK1jWQnucnia-SZ8d2QhHdpIH | F6: Служба проектирования и инженерных изысканий | G6: Служба РП | I6: Отпуск | J6: 44568 | L6: Сервис | M6: Сервис | O6: Презентация
C7: Данные персонала\АЙВИС | D7: 1LE8X6P3FZAduk-24IS0d_KEraASIhefy | F7: Участок по ремонту и техническому обслуживанию КИПиА и АСУТП | G7: Уч. ремонта и ТО КИПиА и АСУТП (НК) | I7: Больничный | J7: 44615 | L7: Отпуск | M7: Отпуск | O7: Структурная схема
C8: ImportExport\Google->1C\Реестр проектов | D8: 1uPiBOtOaJqbuM_MNdB6MYVuRlZ0vfNEg | F8: Отдел закупок и материально-технического обеспечения | G8: ОЗиМТО | J8: 44627 | L8: Отгул | M8: Отгул | O8: Оформление
F9: Тендерный отдел | G9: Тендерный отдел | J9: 44628 | L9: Больничный | M9: Больничный | O9: Коммерческая смета
F10: Служба программного обеспечения | G10: Служба ПО | J10: 44683 | L10: Обучение | M10: Обучение | O10: Анализ/ подготовка данных
F11: Служба главных специалистов | G11: Служба ГС | J11: 44684 | L11: Текущие работы | M11: Текущие работы
F12: Бухгалтерия | G12: Бухгалтерия | J12: 44690 | L12: Бухучет | M12: Бухучет
F13: Финансово-аналитический отдел | G13: Управление | J13: 44691 | L13: АХО | M13: АХО
F14: Участок по монтажу электротехнического оборудования | G14: ЭТД | J14: 44725 | L14: Финансы | M14: Финансы
F15: Отдел поддержки программного обеспечения | G15: Отдел поддержки ПО | J15: 44803 | L15: Договора | M15: Договора
F16: Отдел подготовки технической документации | G16: Отдел подготовки ТД | J16: 44869 | L16: Тендер | M16: Тендер
F17: Договорной отдел | G17: Договорной отдел | L17: Маркетинг | M17: Маркетинг
F18: Отдел кадров | G18: Отдел кадров | L18: Проектный офис | M18: Проектный офис
F19: Служба сервисного обслуживания АСУТП | G19: Служба СО АСУТП | L19: Дежурство на объекте | M19: Дежурство на объекте
F20: Отдел охраны труда и техники безопасности | G20: Отдел ОТ и ТБ | L20: Ожидание вызова | M20: Ожидание вызова
F21: Отдел документационного обеспечения | G21: Отдел ДО | L21: Выделенная работа | M21: Выделенная работа
F22: Отдел информационных технологий | G22: Отдел ИТ | L22: Экономист | M22: Экономист
F23: Управление | G23: Управление | L23: Работа по кадрам | M23: Работа по кадрам
F24: Служба метрологического обеспечения | G24: Служба МО | L24: Работа по ТБ | M24: Работа по ТБ
F25: Электротехническая лаборатория | G25: Служба диагностики и ТК | L25: Другое | M25: Другое
F26: Технический отдел | G26: ЭТД | K26: 120 | L26: ЭГРЭС-1 АСУ ТП топливоподачи | M26: =K26&". "&L26 -> 120. ЭГРЭС-1 АСУ ТП топливоподачи | N26: Корсаков С.Е.
F27: Служба проектирования | G27: Служба РП | K27: 145 | L27: ГродноТЭЦ-2 АСУ ТП ТГ2 | M27: =K27&". "&L27 -> 145. ГродноТЭЦ-2 АСУ ТП ТГ2 | N27: Гуляев С.А.
F28: Служба главных специалистов | G28: Служба ГС | K28: 167 | L28: НорНикель АСУ ТП КА6шт. ПНР | M28: =K28&". "&L28 -> 167. НорНикель АСУ ТП КА6шт. ПНР | N28: Сергеев А.Н.
F29: Служба наладки и испытаний | G29: Служба наладки | K29: 211 | L29: ЗеленПТС АСУ ТП КА | M29: =K29&". "&L29 -> 211. ЗеленПТС АСУ ТП КА | N29: Сергеев А.Н.
F30: Служба программного обеспечения | G30: Служба ПО | K30: 223 | L30: СарТЭЦ АСУ ТП КА9, ГРП-1 Сервис | M30: =K30&". "&L30 -> 223. СарТЭЦ АСУ ТП КА9, ГРП-1 Сервис | N30: Хомин В.П.
F31: Служба проектирования | G31: Служба РП | K31: 228 | L31: АстТЭЦ-2 АСУ ТП ТА6 | M31: =K31&". "&L31 -> 228. АстТЭЦ-2 АСУ ТП ТА6
F32: Управление, Технический отдел | G32: Управление | K32: 256 | L32: КрасТЭЦ АСУ ТП ТГ9 | M32: =K32&". "&L32 -> 256. КрасТЭЦ АСУ ТП ТГ9 | N32: Воронов А.Н.
F33: Сотрудники Казахстан | G33: Сотрудники РК | K33: 276 | L33: Гвинея АСУ ТП КА4 | M33: =K33&". "&L33 -> 276. Гвинея АСУ ТП КА4 | N33: Хомин В.П.
F34: Программист | G34: Программист | K34: 3 | L34: АстТЭЦ-3 АСУ ТП ПК1, ВК1,2,3,4 | M34: =K34&". "&L34 -> 3. АстТЭЦ-3 АСУ ТП ПК1, ВК1,2,3,4
F35: Отдел снабжения | G35: ОЗиМТО | K35: 6 | L35: Карелия Русский Радиатор АСОДУ | M35: =K35&". "&L35 -> 6. Карелия Русский Радиатор АСОДУ
K36: 7 | L36: Магадан РиМ Поставка КИП | M36: =K36&". "&L36 -> 7. Магадан РиМ Поставка КИП | N36: Насырзянов Н.И.
K37: 10 | L37: Воронеж ТЭЦ-2 АСУ ТП КУП-1 ПИР | M37: =K37&". "&L37 -> 10. Воронеж ТЭЦ-2 АСУ ТП КУП-1 ПИР | N37: Бирюков А.Ю.
K38: 11 | L38: НКТЭЦ-2 АСУТП ПТН | M38: =K38&". "&L38 -> 11. НКТЭЦ-2 АСУТП ПТН | N38: Семенов В.А.
K39: 13 | L39: НКГЭС САУ, вибрация ГА 1,2 ПИР | M39: =K39&". "&L39 -> 13. НКГЭС САУ, вибрация ГА 1,2 ПИР | N39: Латипов А.А.
K40: 16 | L40: CарТЭЦ АСУ ТП ТГ9 ПНР | M40: =K40&". "&L40 -> 16. CарТЭЦ АСУ ТП ТГ9 ПНР | N40: Хомин В.П.
...

Sheet old Отделы 2020
A1: Список | B1: Генерация файлов отчетов | C1: Status create | D1: Сокращенное имя | E1: Участие в расчете коэф-та сложности бесполезная штука но нужна | F1: URL папки отдела | G1: URL rкниги отдела | H1: Создавать для этой службы табель? | I1: 25
A2: Служба диагностики и ТК | B2: нет | C2: FALSE | D2: Служба диагностики и ТК | F2: 1BUTSbmUXoeIFqDoW3BTJU4SS9ZYYCapl | G2: 1GrVD5GTtPNVbxTAzO9C8VyQgrcTG85eibMSDPADKPtk | H2: FALSE
A3: Служба ПО | B3: да | C3: FALSE | D3: Служба ПО | F3: 1fDwv_PDcKMkkQiu2YSrKu1rhuAmZOREY | G3: 1SlHfTi27CNkJ0wimctBVuXBpLudOLoufLvkjA2egGNo | H3: TRUE
A4: Уч. сборки | B4: да | C4: FALSE | D4: Уч. сборки | F4: 19tbOUcAMw5F5A8QS9zOB9dWKXLMysBsp | G4: 1HbQMbTB8Giy-PPMBhsRPlhNGGscGtk6EEIJL_GBHldk | H4: TRUE
A5: Уч. монтажа КИПиА и АСУТП (Ел) | B5: нет | C5: FALSE | D5: Уч. монтажа КИПиА и АСУТП (Ел) | H5: FALSE
A6: Служба наладки | B6: да | C6: FALSE | D6: Служба наладки | F6: 1awxmEfkXK5UrHrIC0wLF4LzAVfPhZy_L | G6: 1M6Ugr4bms3ugAwqpqd_s8oA3i7MoNpv0_i7G6DdNydI | H6: TRUE
A7: Служба РП | B7: да | C7: FALSE | D7: Служба РП | F7: 1Y7RjlxP8qE74l4mnuO8arN3_0vGXuLcy | G7: 1SamUrkg_yc8YKYC5vm9ZlqDZbscGYNigusN7BerrIxg | H7: TRUE
A8: Уч. ремонта и ТО КИПиА и АСУТП (НК) | B8: нет | C8: FALSE | D8: Уч. ремонта и ТО КИПиА и АСУТП (НК) | H8: FALSE
A9: ОЗиМТО | B9: да | C9: FALSE | D9: ОЗиМТО | F9: 1nSyMuQ_xSRtCwiZ9_o95FCKTB8MeA4WG | G9: 1hxRxzMFxXhbo66YOojwXu8Al-gQmzeZR-aMTHTkpulU | H9: TRUE
A10: Тендерный отдел | B10: да | C10: FALSE | D10: Тендерный отдел | F10: 14BCGkDMMbXGpF28Hg5wtQSge9CFHzskr | G10: 1yvQiWxIb6kWwBVW73BxeEmG7AHzmUawtXwWkx-EmjYY | H10: TRUE
A11: Служба ГС | B11: да | C11: FALSE | D11: Служба ГС | F11: 1VXCAo2hjyftpafQg2vqICQwmfM4LEQnL | G11: 1kCAOEq-BpSHOn-KjE7cW9wnYoaJgJ0fM7W95RnGbeXs | H11: TRUE
A12: Бухгалтерия | B12: нет | C12: FALSE | D12: Бухгалтерия | F12: 1edafAz_wyH2w0DO_RJHos7DaptCdlr1O | G12: 1t4x40SOnjgMU59B2f7ejZZudFVfQrpCwFONZVzSMzMs | H12: FALSE
A13: Управление | B13: да | C13: FALSE | D13: Управление | F13: 1LdcVo7at0VQVE40Y7eI54USH0kYKzWVs | G13: 1dcQoBF8L44JnQkz9f8HXmgLJ9sXDzM5uQJkEky42QEM | H13: TRUE
A14: ЭТД | B14: нет | C14: FALSE | D14: ЭТД | F14: 1e2gB9fSliZlWnTYGMgPu0bmQGb1-zagu | G14: 1_Q61JjBcwccoMPzxjeUG1BTZNqDDGaRZs2uMMOCQVuk | H14: FALSE
A15: Отдел поддержки ПО | B15: нет | C15: FALSE | D15: Отдел поддержки ПО | F15: 1GcoG2OjGZ1Vlu-_jxmptcJJ2H_uZXpmO | G15: 1mQfOs9umtUhKNX9KN7kxPKn0yve0FZ5SYQyMOn_7nY4 | H15: FALSE
A16: Отдел подготовки ТД | B16: да | C16: FALSE | D16: Отдел подготовки ТД | F16: 1D0_Vzn1V_pjaTyvRIeC6IRZZD1r-pWJe | G16: 13YNarhmp5-93bW5Iu5Yz67O3IkaaudUV5FyynijPrF4 | H16: TRUE
A17: Договорной отдел | B17: нет | C17: FALSE | D17: Договорной отдел | F17: 1K1dvltbijuH1drTOO4viUFxKXndHH9Rg | G17: 1wNBNN44qZJcxoGjxukUP45wie_-kA14cbao84Y3HMjA | H17: FALSE
A18: Отдел кадров | B18: нет | C18: FALSE | D18: Отдел кадров | F18: 1stRzRu53SukZZ2TAiJGk1xvq4owREt34 | G18: 17Wd7y5B27JAInx4ftsTJBcvvam6AY6gr4iI_tZKRiyo | H18: FALSE
A19: Служба СО АСУТП | B19: нет | C19: FALSE | D19: Служба СО АСУТП | H19: FALSE
A20: Отдел ОТ и ТБ | B20: нет | C20: FALSE | D20: Отдел ОТ и ТБ | F20: 1CWEM9b5chaDOvwnRTyR-jD7hjswpUrIk | G20: 1knJcvTIu5omO4_7-a6NWFlVnRBhKu6xGwKDziMrjCAI | H20: FALSE
A21: Отдел ДО | B21: нет | C21: FALSE | D21: Отдел ДО | F21: 1ECaAo4eWnRFXbZDN9kur2V2MolZDm_hP | G21: 1kuIpOEXPBGVgsIKJI1NO8scCjTKoY_q5cyfkhbHqXeA | H21: FALSE
A22: Отдел ИТ | B22: нет | C22: FALSE | D22: Отдел ИТ | F22: 1KNwoF2pQmh2VJwiuz0qQb9eoKIbJmbFb | G22: 16IrW4b9xWx1WMkxiyQ8Z2GMKuiBmB9SyLqaeKsfhp8Y | H22: FALSE
A23: Служба МО | B23: нет | C23: FALSE | D23: Служба МО | H23: FALSE
A24: Сотрудники РК | B24: да | C24: FALSE | D24: Сотрудники РК | F24: 1XHxhlHUQXfwrhIzxymtW5IjaZazowAJq | G24: 1qmlm7P5RnD0E8QqSU5JBIj_TCK604USkiLAr6GM42K0 | H24: TRUE
A25: Программист | B25: да | C25: FALSE | D25: Программист | F25: 1_vMhPy-jHqy4QMkFaYziDK9RNdf2zKTx | G25: 1tNgSFkuDateyUmwjc9jtcDzON6sgciM6gmBIst67ZO4 | H25: TRUE

Sheet Test
A1: kse.keravt@gmail.com | C1: ktunameold | D1: ktumailsold | F1: ktuname | G1: ktumail
A2: [20-02-10 19:16:33:724 MSK] zvg.keravt@gmail.com
A3: [20-02-10 19:16:34:395 MSK] sme.keravt@gmail.com
A4: [20-02-10 19:16:34:396 MSK] ker.shugaevame@gmail.com
A5: [20-02-10 19:16:34:397 MSK] moa.keravt@gmail.com
A6: [20-02-10 19:16:34:398 MSK] hey.keravt@gmail.com
A7: [20-02-10 19:16:34:398 MSK] sam.keravt@gmail.com
A8: [20-02-10 19:16:34:399 MSK] bvi.keravt@gmail.com
A9: [20-02-10 19:16:34:400 MSK] pva.keravt@gmail.com
A10: [20-02-10 19:16:34:401 MSK] asv.keravt@gmail.com
A11: [20-02-10 19:16:34:402 MSK] kse.keravt@gmail.com
A12: [20-02-10 19:16:34:402 MSK] sergeevan.keravt@gmail.com
A13: [20-02-10 19:16:34:403 MSK] nni.keravt@gmail.com
... A26: [20-02-10 19:16:34:413 MSK] srt.keravt@gmail.com
